{
 "cells": [
  {
   "cell_type": "code",
   "execution_count": null,
   "id": "03a3c706",
   "metadata": {},
   "outputs": [],
   "source": [
    "## Describe three applications for exception processing."
   ]
  },
  {
   "cell_type": "code",
   "execution_count": null,
   "id": "a014d1f9",
   "metadata": {},
   "outputs": [],
   "source": [
    "## Exception processing is an important concept in Python programming that allows developers to handle errors and exceptions \n",
    "that occur during the execution of a program. Here are three applications for exception processing in Python:\n",
    "\n",
    "File Input/Output: When working with files in Python, exception processing can be used to handle errors that occur during file \n",
    "    input/output operations. For example, if a file is not found or cannot be opened, an exception can be raised and handled\n",
    "    in the code. By handling these exceptions gracefully, the program can continue to execute without crashing.\n",
    "\n",
    "Web Scraping: Exception processing can also be used in web scraping applications to handle errors that occur when accessing \n",
    "    web pages or data sources. For example, if a web page cannot be accessed or the data is not in the expected format, an\n",
    "    exception can be raised and handled in the code. By handling these exceptions gracefully, the program can continue to\n",
    "    scrape data from other sources without crashing.\n",
    "\n",
    "Database Access: Exception processing can be used in Python applications that interact with databases to handle errors that \n",
    "    occur during database access. For example, if a database connection cannot be established or a query fails, an exception \n",
    "    can be raised and handled in the code. By handling these exceptions gracefully, the program can continue to interact with\n",
    "    the database without crashing.\n",
    "\n",
    "Overall, exception processing is a powerful tool in Python that can be used to handle errors and exceptions in a variety of applications, from file input/output to web scraping and database access. By handling exceptions gracefully, Python programs can continue to execute and deliver useful results even in the face of unexpected errors or exceptions.\n",
    "\n",
    "\n"
   ]
  },
  {
   "cell_type": "code",
   "execution_count": null,
   "id": "6d6d2480",
   "metadata": {},
   "outputs": [],
   "source": [
    "## What happens if you don't do something extra to treat an exception?"
   ]
  },
  {
   "cell_type": "code",
   "execution_count": null,
   "id": "27342783",
   "metadata": {},
   "outputs": [],
   "source": [
    "## If an exception is not handled properly in a program, it can cause the program to crash or produce unexpected results.\n",
    "When an exception occurs during the execution of a program, the normal flow of the program is interrupted, and the interpreter\n",
    "looks for an exception handler to handle the error.\n",
    "\n",
    "If no exception handler is found, the interpreter will terminate the program and display an error message to the user. \n",
    "This can be frustrating for users and can also cause data loss or corruption if the program was in the middle of an important\n",
    "operation.\n",
    "\n",
    "In addition to crashing the program, unhandled exceptions can also leave the system in an inconsistent state. For example,\n",
    "if a program was in the middle of updating a database or file when an exception occurred, the data may be left in an \n",
    "inconsistent state, leading to errors or corruption later on.\n",
    "\n",
    "To avoid these problems, it's important to handle exceptions properly in a program. This means anticipating possible errors\n",
    "and exceptions and writing code to handle them gracefully, whether by providing a user-friendly error message, logging the \n",
    "error, or retrying the operation that caused the error. Proper exception handling can help to ensure that a program runs\n",
    "smoothly and produces reliable results, even in the face of unexpected errors or exceptions.\n",
    "\n",
    "\n",
    "\n",
    "\n"
   ]
  },
  {
   "cell_type": "code",
   "execution_count": null,
   "id": "44afd293",
   "metadata": {},
   "outputs": [],
   "source": [
    "## What are your options for recovering from an exception in your script?"
   ]
  },
  {
   "cell_type": "code",
   "execution_count": null,
   "id": "cbc9c495",
   "metadata": {},
   "outputs": [],
   "source": [
    "## When an exception occurs in a Python script, there are several options for recovering from the error and continuing\n",
    "execution:\n",
    "\n",
    "Catch the Exception and Continue: The simplest way to recover from an exception is to catch the exception using a try-except\n",
    "    block and continue execution. In this case, the code in the except block can handle the error or log it for later analysis,\n",
    "    and the program can continue running. Here's an example:\n",
    "python\n",
    "Copy code\n",
    "try:\n",
    "    # code that might raise an exception\n",
    "except Exception as e:\n",
    "    # code to handle the exception\n",
    "Retry the Operation: In some cases, it may be possible to recover from an exception by retrying the operation that caused the\n",
    "    error. For example, if a network connection error occurs when downloading a file, the program can retry the download a\n",
    "    certain number of times before giving up.\n",
    "\n",
    "Raise a Different Exception: Sometimes it might be appropriate to raise a different exception than the one that was originally \n",
    "    raised, to provide more context or information about the error. For example, if an invalid argument is passed to a function, the function can raise a ValueError with a specific message to indicate what went wrong.\n",
    "\n",
    "Graceful Termination: In some cases, it might not be possible to recover from an exception, and the program needs to terminate \n",
    "    gracefully. In this case, the code can use the sys.exit() function to terminate the program with a specific exit code,\n",
    "    indicating the reason for the termination.\n",
    "\n",
    "Overall, the key to recovering from exceptions in Python is to handle them gracefully and provide clear error messages or\n",
    "logging information to help diagnose and fix the issue.\n",
    "\n",
    "\n",
    "\n",
    "\n",
    "Regenerate response"
   ]
  },
  {
   "cell_type": "code",
   "execution_count": null,
   "id": "c4d6417d",
   "metadata": {},
   "outputs": [],
   "source": [
    "## Describe two methods for triggering exceptions in your script."
   ]
  },
  {
   "cell_type": "code",
   "execution_count": null,
   "id": "c81fbb26",
   "metadata": {},
   "outputs": [],
   "source": [
    "## In Python, there are many built-in exceptions that can be triggered automatically by the interpreter when certain types of \n",
    "errors occur. However, it's also possible for developers to trigger their own exceptions in a script using two methods:\n",
    "\n",
    "Raise an Exception Manually: One way to trigger an exception in Python is to raise an exception manually using the raise \n",
    "    keyword. This allows you to create a custom exception with a specific message or error code. Here's an example:\n",
    "python\n",
    "Copy code\n",
    "raise Exception(\"This is a custom exception\")\n",
    "In this example, we're manually raising an exception with the message \"This is a custom exception\". When the interpreter\n",
    "encounters this line of code, it will stop executing and raise the exception, which can then be caught and handled using a \n",
    "try-except block.\n",
    "\n",
    "Use an Assertion: Another way to trigger an exception in Python is to use an assertion. An assertion is a statement that checks\n",
    "    for a certain condition and raises an AssertionError if the condition is not met. Here's an example:\n",
    "python\n",
    "Copy code\n",
    "x = 5\n",
    "assert x == 10, \"x must be equal to 10\"\n",
    "In this example, we're using an assertion to check whether the value of x is equal to 10. If x is not equal to 10, \n",
    "an AssertionError will be raised with the message \"x must be equal to 10\". Assertions are typically used to check for \n",
    "conditions that should never occur in normal execution, and can help to catch logic errors or other issues in a program.\n",
    "\n",
    "Overall, triggering exceptions manually or using assertions can be a useful way to handle unexpected conditions in a Python \n",
    "script and provide more information about what went wrong. By using these methods carefully and thoughtfully, developers can\n",
    "create more robust and reliable code that can handle a variety of situations."
   ]
  },
  {
   "cell_type": "code",
   "execution_count": null,
   "id": "d401aa6b",
   "metadata": {},
   "outputs": [],
   "source": [
    "##  Identify two methods for specifying actions to be executed at termination time, regardless of\n",
    "whether or not an exception exists."
   ]
  },
  {
   "cell_type": "code",
   "execution_count": null,
   "id": "b01e7ac9",
   "metadata": {},
   "outputs": [],
   "source": [
    "## In Python, there are several methods for specifying actions to be executed at termination time, regardless of whether or \n",
    "not an exception exists in the script. Here are two methods:\n",
    "\n",
    "Using a try-finally block: One common method is to use a try-finally block to ensure that certain actions are executed at \n",
    "    termination time, regardless of whether or not an exception is raised. Here's an example:\n",
    "python\n",
    "Copy code\n",
    "try:\n",
    "    # code that might raise an exception\n",
    "finally:\n",
    "    # code that should always be executed\n",
    "In this example, the code in the try block is executed normally, and if an exception is raised, the code in the\n",
    "finally block is executed before the exception is propagated. The code in the finally block can be used to perform \n",
    "cleanup tasks, such as closing files or releasing resources.\n",
    "\n",
    "Using an atexit function: Another method is to use an atexit function to register a function that will be executed \n",
    "    at termination time, regardless of whether or not an exception is raised. Here's an example:\n",
    "python\n",
    "Copy code\n",
    "import atexit\n",
    "\n",
    "def cleanup():\n",
    "    # code that should always be executed\n",
    "\n",
    "atexit.register(cleanup)\n",
    "In this example, the cleanup function is registered using the atexit.register() function, which ensures that the \n",
    "function will be called when the script exits normally. This method can be useful for performing cleanup tasks that\n",
    "should always be executed, even if the script terminates unexpectedly due to an exception.\n",
    "\n",
    "Overall, by using try-finally blocks or atexit functions, developers can ensure that certain actions are always \n",
    "executed at termination time, regardless of whether or not an exception exists in the script. This can help to make\n",
    "code more reliable and robust, and ensure that resources are properly released and cleanup tasks are performed as needed.\n",
    "\n",
    "\n",
    "\n"
   ]
  }
 ],
 "metadata": {
  "kernelspec": {
   "display_name": "Python 3 (ipykernel)",
   "language": "python",
   "name": "python3"
  },
  "language_info": {
   "codemirror_mode": {
    "name": "ipython",
    "version": 3
   },
   "file_extension": ".py",
   "mimetype": "text/x-python",
   "name": "python",
   "nbconvert_exporter": "python",
   "pygments_lexer": "ipython3",
   "version": "3.9.12"
  }
 },
 "nbformat": 4,
 "nbformat_minor": 5
}
